Workbook

Sheet README
A1: Pelvic Fx Game — Evaluation workbook
A3: Content version | B3: ptd-minigame-draft-2026-10-07
A4: How it fills | B4: Teacher → app → Faculty → 'Update Google Sheet now'. Raw tabs are replaced each time; analysis tabs recalculate. Manual Exclusions and Handover Scoring are yours and are never overwritten.
A5: Who is counted | B5: Statistics use only rows where 'Exclude from analysis' is FALSE. QA/DEMO/TEST IDs, practice attempts and anyone in Manual Exclusions are excluded automatically but stay visible.
A6: Learning objectives | B6: LO1 mechanism & associated injuries · LO2 history & examination · LO3 imaging choice & interpretation · LO4 open vs closed fracture · LO5 initial treatment (shock, resuscitation, open fracture) · LO6 pelvic binder · LO7 referral & handover.
A7: Design | B7: Pre-test (8 items) → 24 practice stations with feedback and correction → boss reviews → post-test (8 items, parallel form). Formative, supervised learning; not a certification of competence.
A8: Pass standard | B8: Post-test ≥ 6/8 correct on the first try AND both must-pass safety items correct (FS2 no Foley with meatal blood; FS6 binder at the greater trochanters). A conjunctive standard: high marks cannot compensate for a safety error.
A9: Raw gain | B9: Post-test score − pre-test score (same 8-item blueprint, other form).
A10: Normalized gain (g) | B10: Hake: (post − pre) / (8 − pre). 0.3–0.7 = medium, > 0.7 = high. Fairer than raw gain when pre-test scores differ.
A11: Paired t / p / dz | B11: Pre-Post by Cohort: paired t-test of gain (df = n − 1), two-sided p from TDIST, Cohen's dz = mean gain / SD of gain (0.2 small, 0.5 medium, 0.8 large).
A12: Difficulty p | B12: Item Analysis: proportion correct on the first try. < 0.30 = very hard (check the teaching or the item); > 0.90 = very easy.
A13: Discrimination D | B13: First-try rate of the upper 27% minus the lower 27% of learners by post-test score. D < 0.20 suggests the item does not separate stronger and weaker learners. Needs at least 4 included learners.
A14: Bloom level | B14: Station task type: remember · understand · apply · analyse. Use it to check items do not all test recall.
... A18: Privacy | B18: Contains student identifiers and free text. Keep the sheet private (never 'anyone with the link'); share only with course teachers. Delete or anonymise at the end of the retention period.

Sheet Dashboard
A1: Class dashboard
A2: Included learners only (Exclude = FALSE). Recalculates automatically.
A4: Enrolled | B4: =COUNTIFS('Roster'!$E$2:$E$5000,FALSE)
A5: Started | B5: =COUNTIFS('Roster'!$C$2:$C$5000,"yes",'Roster'!$E$2:$E$5000,FALSE)
A6: Completed the shift | B6: =COUNTIFS('Roster'!$D$2:$D$5000,"yes",'Roster'!$E$2:$E$5000,FALSE)
A7: Finished the post-test | B7: =COUNTIFS('Attempts'!$K$2:$K$5000,">=0",'Attempts'!$AC$2:$AC$5000,FALSE)
A8: Met the pass standard | B8: =COUNTIFS('Attempts'!$M$2:$M$5000,TRUE,'Attempts'!$AC$2:$AC$5000,FALSE)
A9: Pass rate | B9: =IFERROR(B8/B7,"")
A10: Mean pre-test /8 | B10: =IFERROR(AVERAGEIFS('Attempts'!$J$2:$J$5000,'Attempts'!$J$2:$J$5000,">=0",'Attempts'!$AC$2:$AC$5000,FALSE),"")
A11: Mean post-test /8 | B11: =IFERROR(AVERAGEIFS('Attempts'!$K$2:$K$5000,'Attempts'!$K$2:$K$5000,">=0",'Attempts'!$AC$2:$AC$5000,FALSE),"")
A12: Mean normalized gain (g) | B12: =IFERROR(AVERAGEIFS('Attempts'!$O$2:$O$5000,'Attempts'!$O$2:$O$5000,">=-1",'Attempts'!$AC$2:$AC$5000,FALSE),"")
A13: Mean time on task (min) | B13: =IFERROR(AVERAGEIFS('Attempts'!$S$2:$S$5000,'Attempts'!$S$2:$S$5000,">0",'Attempts'!$AC$2:$AC$5000,FALSE),"")
A14: Course feedback — useful (1–5) | B14: =IFERROR(AVERAGEIFS('Course Feedback'!$F$2:$F$5000,'Course Feedback'!$J$2:$J$5000,FALSE),"")
A15: Course feedback — enjoyable (1–5) | B15: =IFERROR(AVERAGEIFS('Course Feedback'!$G$2:$G$5000,'Course Feedback'!$J$2:$J$5000,FALSE),"")
A16: Course feedback — confidence (1–5) | B16: =IFERROR(AVERAGEIFS('Course Feedback'!$H$2:$H$5000,'Course Feedback'!$J$2:$J$5000,FALSE),"")
A18: See: Objective Summary · Item Analysis · Pre-Post by Cohort · Misconceptions

Sheet Objective Summary
A1: Objective | B1: Description | C1: Practice stations | D1: Practice responses (n) | E1: Practice first-try % | F1: Corrected after feedback % | G1: Pre-test first-try % | H1: Post-test first-try % | I1: Change (post − pre)
A2: LO1 | B2: Mechanism of injury and associated injuries | C2: 5 | D2: =COUNTIFS('Station Responses'!$H$2:$H$5000,"*LO1*",'Station Responses'!$E$2:$E$5000,"practice",'Station Responses'!$T$2:$T$5000,FALSE) | E2: =IFERROR(AVERAGEIFS('Station Responses'!$K$2:$K$5000,'Station Responses'!$H$2:$H$5000,"*LO1*",'Station Responses'!$E$2:$E$5000,"practice",'Station Responses'!$T$2:$T$5000,FALSE),"") | F2: =IFERROR(COUNTIFS('Station Responses'!$H$2:$H$5000,"*LO1*",'Station Responses'!$E$2:$E$5000,"practice",'Station Responses'!$K$2:$K$5000,0,'Station Responses'!$L$2:$L$5000,1,'Station Responses'!$T$2:$T$5000,FALSE)/COUNTIFS('Station Responses'!$H$2:$H$5000,"*LO1*",'Station Responses'!$E$2:$E$5000,"practice",'Station Responses'!$K$2:$K$5000,0,'Station Responses'!$T$2:$T$5000,FALSE),"") | G2: =IFERROR(AVERAGEIFS('Station Responses'!$K$2:$K$5000,'Station Responses'!$H$2:$H$5000,"*LO1*",'Station Responses'!$E$2:$E$5000,"pre-test",'Station Responses'!$T$2:$T$5000,FALSE),"") | H2: =IFERROR(AVERAGEIFS('Station Responses'!$K$2:$K$5000,'Station Responses'!$H$2:$H$5000,"*LO1*",'Station Responses'!$E$2:$E$5000,"post-test",'Station Responses'!$T$2:$T$5000,FALSE),"") | I2: =IFERROR(H2-G2,"")
A3: LO2 | B3: History and physical examination | C3: 5 | D3: =COUNTIFS('Station Responses'!$H$2:$H$5000,"*LO2*",'Station Responses'!$E$2:$E$5000,"practice",'Station Responses'!$T$2:$T$5000,FALSE) | E3: =IFERROR(AVERAGEIFS('Station Responses'!$K$2:$K$5000,'Station Responses'!$H$2:$H$5000,"*LO2*",'Station Responses'!$E$2:$E$5000,"practice",'Station Responses'!$T$2:$T$5000,FALSE),"") | F3: =IFERROR(COUNTIFS('Station Responses'!$H$2:$H$5000,"*LO2*",'Station Responses'!$E$2:$E$5000,"practice",'Station Responses'!$K$2:$K$5000,0,'Station Responses'!$L$2:$L$5000,1,'Station Responses'!$T$2:$T$5000,FALSE)/COUNTIFS('Station Responses'!$H$2:$H$5000,"*LO2*",'Station Responses'!$E$2:$E$5000,"practice",'Station Responses'!$K$2:$K$5000,0,'Station Responses'!$T$2:$T$5000,FALSE),"") | G3: =IFERROR(AVERAGEIFS('Station Responses'!$K$2:$K$5000,'Station Responses'!$H$2:$H$5000,"*LO2*",'Station Responses'!$E$2:$E$5000,"pre-test",'Station Responses'!$T$2:$T$5000,FALSE),"") | H3: =IFERROR(AVERAGEIFS('Station Responses'!$K$2:$K$5000,'Station Responses'!$H$2:$H$5000,"*LO2*",'Station Responses'!$E$2:$E$5000,"post-test",'Station Responses'!$T$2:$T$5000,FALSE),"") | I3: =IFERROR(H3-G3,"")
A4: LO3 | B4: Choose and interpret imaging | C4: 6 | D4: =COUNTIFS('Station Responses'!$H$2:$H$5000,"*LO3*",'Station Responses'!$E$2:$E$5000,"practice",'Station Responses'!$T$2:$T$5000,FALSE) | E4: =IFERROR(AVERAGEIFS('Station Responses'!$K$2:$K$5000,'Station Responses'!$H$2:$H$5000,"*LO3*",'Station Responses'!$E$2:$E$5000,"practice",'Station Responses'!$T$2:$T$5000,FALSE),"") | F4: =IFERROR(COUNTIFS('Station Responses'!$H$2:$H$5000,"*LO3*",'Station Responses'!$E$2:$E$5000,"practice",'Station Responses'!$K$2:$K$5000,0,'Station Responses'!$L$2:$L$5000,1,'Station Responses'!$T$2:$T$5000,FALSE)/COUNTIFS('Station Responses'!$H$2:$H$5000,"*LO3*",'Station Responses'!$E$2:$E$5000,"practice",'Station Responses'!$K$2:$K$5000,0,'Station Responses'!$T$2:$T$5000,FALSE),"") | G4: =IFERROR(AVERAGEIFS('Station Responses'!$K$2:$K$5000,'Station Responses'!$H$2:$H$5000,"*LO3*",'Station Responses'!$E$2:$E$5000,"pre-test",'Station Responses'!$T$2:$T$5000,FALSE),"") | H4: =IFERROR(AVERAGEIFS('Station Responses'!$K$2:$K$5000,'Station Responses'!$H$2:$H$5000,"*LO3*",'Station Responses'!$E$2:$E$5000,"post-test",'Station Responses'!$T$2:$T$5000,FALSE),"") | I4: =IFERROR(H4-G4,"")
A5: LO4 | B5: Open vs closed pelvic fracture | C5: 4 | D5: =COUNTIFS('Station Responses'!$H$2:$H$5000,"*LO4*",'Station Responses'!$E$2:$E$5000,"practice",'Station Responses'!$T$2:$T$5000,FALSE) | E5: =IFERROR(AVERAGEIFS('Station Responses'!$K$2:$K$5000,'Station Responses'!$H$2:$H$5000,"*LO4*",'Station Responses'!$E$2:$E$5000,"practice",'Station Responses'!$T$2:$T$5000,FALSE),"") | F5: =IFERROR(COUNTIFS('Station Responses'!$H$2:$H$5000,"*LO4*",'Station Responses'!$E$2:$E$5000,"practice",'Station Responses'!$K$2:$K$5000,0,'Station Responses'!$L$2:$L$5000,1,'Station Responses'!$T$2:$T$5000,FALSE)/COUNTIFS('Station Responses'!$H$2:$H$5000,"*LO4*",'Station Responses'!$E$2:$E$5000,"practice",'Station Responses'!$K$2:$K$5000,0,'Station Responses'!$T$2:$T$5000,FALSE),"") | G5: =IFERROR(AVERAGEIFS('Station Responses'!$K$2:$K$5000,'Station Responses'!$H$2:$H$5000,"*LO4*",'Station Responses'!$E$2:$E$5000,"pre-test",'Station Responses'!$T$2:$T$5000,FALSE),"") | H5: =IFERROR(AVERAGEIFS('Station Responses'!$K$2:$K$5000,'Station Responses'!$H$2:$H$5000,"*LO4*",'Station Responses'!$E$2:$E$5000,"post-test",'Station Responses'!$T$2:$T$5000,FALSE),"") | I5: =IFERROR(H5-G5,"")
A6: LO5 | B6: Initial treatment: shock, resuscitation, open fracture | C6: 8 | D6: =COUNTIFS('Station Responses'!$H$2:$H$5000,"*LO5*",'Station Responses'!$E$2:$E$5000,"practice",'Station Responses'!$T$2:$T$5000,FALSE) | E6: =IFERROR(AVERAGEIFS('Station Responses'!$K$2:$K$5000,'Station Responses'!$H$2:$H$5000,"*LO5*",'Station Responses'!$E$2:$E$5000,"practice",'Station Responses'!$T$2:$T$5000,FALSE),"") | F6: =IFERROR(COUNTIFS('Station Responses'!$H$2:$H$5000,"*LO5*",'Station Responses'!$E$2:$E$5000,"practice",'Station Responses'!$K$2:$K$5000,0,'Station Responses'!$L$2:$L$5000,1,'Station Responses'!$T$2:$T$5000,FALSE)/COUNTIFS('Station Responses'!$H$2:$H$5000,"*LO5*",'Station Responses'!$E$2:$E$5000,"practice",'Station Responses'!$K$2:$K$5000,0,'Station Responses'!$T$2:$T$5000,FALSE),"") | G6: =IFERROR(AVERAGEIFS('Station Responses'!$K$2:$K$5000,'Station Responses'!$H$2:$H$5000,"*LO5*",'Station Responses'!$E$2:$E$5000,"pre-test",'Station Responses'!$T$2:$T$5000,FALSE),"") | H6: =IFERROR(AVERAGEIFS('Station Responses'!$K$2:$K$5000,'Station Responses'!$H$2:$H$5000,"*LO5*",'Station Responses'!$E$2:$E$5000,"post-test",'Station Responses'!$T$2:$T$5000,FALSE),"") | I6: =IFERROR(H6-G6,"")
A7: LO6 | B7: Pelvic binder: indication and application | C7: 3 | D7: =COUNTIFS('Station Responses'!$H$2:$H$5000,"*LO6*",'Station Responses'!$E$2:$E$5000,"practice",'Station Responses'!$T$2:$T$5000,FALSE) | E7: =IFERROR(AVERAGEIFS('Station Responses'!$K$2:$K$5000,'Station Responses'!$H$2:$H$5000,"*LO6*",'Station Responses'!$E$2:$E$5000,"practice",'Station Responses'!$T$2:$T$5000,FALSE),"") | F7: =IFERROR(COUNTIFS('Station Responses'!$H$2:$H$5000,"*LO6*",'Station Responses'!$E$2:$E$5000,"practice",'Station Responses'!$K$2:$K$5000,0,'Station Responses'!$L$2:$L$5000,1,'Station Responses'!$T$2:$T$5000,FALSE)/COUNTIFS('Station Responses'!$H$2:$H$5000,"*LO6*",'Station Responses'!$E$2:$E$5000,"practice",'Station Responses'!$K$2:$K$5000,0,'Station Responses'!$T$2:$T$5000,FALSE),"") | G7: =IFERROR(AVERAGEIFS('Station Responses'!$K$2:$K$5000,'Station Responses'!$H$2:$H$5000,"*LO6*",'Station Responses'!$E$2:$E$5000,"pre-test",'Station Responses'!$T$2:$T$5000,FALSE),"") | H7: =IFERROR(AVERAGEIFS('Station Responses'!$K$2:$K$5000,'Station Responses'!$H$2:$H$5000,"*LO6*",'Station Responses'!$E$2:$E$5000,"post-test",'Station Responses'!$T$2:$T$5000,FALSE),"") | I7: =IFERROR(H7-G7,"")
A8: LO7 | B8: Referral and handover | C8: 3 | D8: =COUNTIFS('Station Responses'!$H$2:$H$5000,"*LO7*",'Station Responses'!$E$2:$E$5000,"practice",'Station Responses'!$T$2:$T$5000,FALSE) | E8: =IFERROR(AVERAGEIFS('Station Responses'!$K$2:$K$5000,'Station Responses'!$H$2:$H$5000,"*LO7*",'Station Responses'!$E$2:$E$5000,"practice",'Station Responses'!$T$2:$T$5000,FALSE),"") | F8: =IFERROR(COUNTIFS('Station Responses'!$H$2:$H$5000,"*LO7*",'Station Responses'!$E$2:$E$5000,"practice",'Station Responses'!$K$2:$K$5000,0,'Station Responses'!$L$2:$L$5000,1,'Station Responses'!$T$2:$T$5000,FALSE)/COUNTIFS('Station Responses'!$H$2:$H$5000,"*LO7*",'Station Responses'!$E$2:$E$5000,"practice",'Station Responses'!$K$2:$K$5000,0,'Station Responses'!$T$2:$T$5000,FALSE),"") | G8: =IFERROR(AVERAGEIFS('Station Responses'!$K$2:$K$5000,'Station Responses'!$H$2:$H$5000,"*LO7*",'Station Responses'!$E$2:$E$5000,"pre-test",'Station Responses'!$T$2:$T$5000,FALSE),"") | H8: =IFERROR(AVERAGEIFS('Station Responses'!$K$2:$K$5000,'Station Responses'!$H$2:$H$5000,"*LO7*",'Station Responses'!$E$2:$E$5000,"post-test",'Station Responses'!$T$2:$T$5000,FALSE),"") | I8: =IFERROR(H8-G8,"")
A10: Mastery colour: red < 50%, amber 50–79%, green ≥ 80% first try. Per-learner objective % is in Attempts (LO1–LO7 columns).

Sheet Item Analysis
A1: Station | B1: Phase | C1: Case | D1: Title | E1: Objectives | F1: Bloom level | G1: Must-pass | H1: Answered (n) | I1: Difficulty p (first-try) | J1: Corrected after feedback % | K1: Discrimination D | L1: Mean time (s) | M1: Hint use % | N1: Flag | O1: Teaching point
A2: C0S1 | B2: practice | C2: Pelvis Academy | D2: Find the pelvic landmarks | E2: LO1 | F2: remember | G2: FALSE | H2: =COUNTIFS('Station Responses'!$F$2:$F$5000,"C0S1",'Station Responses'!$T$2:$T$5000,FALSE) | I2: =IFERROR(AVERAGEIFS('Station Responses'!$K$2:$K$5000,'Station Responses'!$F$2:$F$5000,"C0S1",'Station Responses'!$T$2:$T$5000,FALSE),"") | J2: =IFERROR(COUNTIFS('Station Responses'!$F$2:$F$5000,"C0S1",'Station Responses'!$T$2:$T$5000,FALSE,'Station Responses'!$K$2:$K$5000,0,'Station Responses'!$L$2:$L$5000,1)/COUNTIFS('Station Responses'!$F$2:$F$5000,"C0S1",'Station Responses'!$T$2:$T$5000,FALSE,'Station Responses'!$K$2:$K$5000,0),"") | K2: =IFERROR(AVERAGEIFS('Station Responses'!$K$2:$K$5000,'Station Responses'!$F$2:$F$5000,"C0S1",'Station Responses'!$T$2:$T$5000,FALSE,'Station Responses'!$S$2:$S$5000,"upper")-AVERAGEIFS('Station Responses'!$K$2:$K$5000,'Station Responses'!$F$2:$F$5000,"C0S1",'Station Responses'!$T$2:$T$5000,FALSE,'Station Responses'!$S$2:$S$5000,"lower"),"") | L2: =IFERROR(AVERAGEIFS('Station Responses'!$P$2:$P$5000,'Station Responses'!$F$2:$F$5000,"C0S1",'Station Responses'!$T$2:$T$5000,FALSE,'Station Responses'!$P$2:$P$5000,">0"),"") | M2: =IFERROR(COUNTIFS('Station Responses'!$F$2:$F$5000,"C0S1",'Station Responses'!$T$2:$T$5000,FALSE,'Station Responses'!$O$2:$O$5000,">0")/H2,"") | N2: =IF(H2<5,"too few answers",IF(I2<0.3,"very hard — review teaching or item",IF(I2>0.9,"very easy",IF(AND(K2<>"",K2<0.2),"low discrimination — review item","OK")))) | O2: The anterior and posterior ring form one linked structure.
A3: C0S2 | B3: practice | C3: Pelvis Academy | D3: Ligaments and their jobs | E3: LO1 | F3: understand | G3: FALSE | H3: =COUNTIFS('Station Responses'!$F$2:$F$5000,"C0S2",'Station Responses'!$T$2:$T$5000,FALSE) | I3: =IFERROR(AVERAGEIFS('Station Responses'!$K$2:$K$5000,'Station Responses'!$F$2:$F$5000,"C0S2",'Station Responses'!$T$2:$T$5000,FALSE),"") | J3: =IFERROR(COUNTIFS('Station Responses'!$F$2:$F$5000,"C0S2",'Station Responses'!$T$2:$T$5000,FALSE,'Station Responses'!$K$2:$K$5000,0,'Station Responses'!$L$2:$L$5000,1)/COUNTIFS('Station Responses'!$F$2:$F$5000,"C0S2",'Station Responses'!$T$2:$T$5000,FALSE,'Station Responses'!$K$2:$K$5000,0),"") | K3: =IFERROR(AVERAGEIFS('Station Responses'!$K$2:$K$5000,'Station Responses'!$F$2:$F$5000,"C0S2",'Station Responses'!$T$2:$T$5000,FALSE,'Station Responses'!$S$2:$S$5000,"upper")-AVERAGEIFS('Station Responses'!$K$2:$K$5000,'Station Responses'!$F$2:$F$5000,"C0S2",'Station Responses'!$T$2:$T$5000,FALSE,'Station Responses'!$S$2:$S$5000,"lower"),"") | L3: =IFERROR(AVERAGEIFS('Station Responses'!$P$2:$P$5000,'Station Responses'!$F$2:$F$5000,"C0S2",'Station Responses'!$T$2:$T$5000,FALSE,'Station Responses'!$P$2:$P$5000,">0"),"") | M3: =IFERROR(COUNTIFS('Station Responses'!$F$2:$F$5000,"C0S2",'Station Responses'!$T$2:$T$5000,FALSE,'Station Responses'!$O$2:$O$5000,">0")/H3,"") | N3: =IF(H3<5,"too few answers",IF(I3<0.3,"very hard — review teaching or item",IF(I3>0.9,"very easy",IF(AND(K3<>"",K3<0.2),"low discrimination — review item","OK")))) | O3: Ligament disruption explains instability clues.
A4: C0S3 | B4: practice | C4: Pelvis Academy | D4: Force detective | E4: LO1 | F4: understand | G4: FALSE | H4: =COUNTIFS('Station Responses'!$F$2:$F$5000,"C0S3",'Station Responses'!$T$2:$T$5000,FALSE) | I4: =IFERROR(AVERAGEIFS('Station Responses'!$K$2:$K$5000,'Station Responses'!$F$2:$F$5000,"C0S3",'Station Responses'!$T$2:$T$5000,FALSE),"") | J4: =IFERROR(COUNTIFS('Station Responses'!$F$2:$F$5000,"C0S3",'Station Responses'!$T$2:$T$5000,FALSE,'Station Responses'!$K$2:$K$5000,0,'Station Responses'!$L$2:$L$5000,1)/COUNTIFS('Station Responses'!$F$2:$F$5000,"C0S3",'Station Responses'!$T$2:$T$5000,FALSE,'Station Responses'!$K$2:$K$5000,0),"") | K4: =IFERROR(AVERAGEIFS('Station Responses'!$K$2:$K$5000,'Station Responses'!$F$2:$F$5000,"C0S3",'Station Responses'!$T$2:$T$5000,FALSE,'Station Responses'!$S$2:$S$5000,"upper")-AVERAGEIFS('Station Responses'!$K$2:$K$5000,'Station Responses'!$F$2:$F$5000,"C0S3",'Station Responses'!$T$2:$T$5000,FALSE,'Station Responses'!$S$2:$S$5000,"lower"),"") | L4: =IFERROR(AVERAGEIFS('Station Responses'!$P$2:$P$5000,'Station Responses'!$F$2:$F$5000,"C0S3",'Station Responses'!$T$2:$T$5000,FALSE,'Station Responses'!$P$2:$P$5000,">0"),"") | M4: =IFERROR(COUNTIFS('Station Responses'!$F$2:$F$5000,"C0S3",'Station Responses'!$T$2:$T$5000,FALSE,'Station Responses'!$O$2:$O$5000,">0")/H4,"") | N4: =IF(H4<5,"too few answers",IF(I4<0.3,"very hard — review teaching or item",IF(I4>0.9,"very easy",IF(AND(K4<>"",K4<0.2),"low discrimination — review item","OK")))) | O4: Mechanism suggests a pattern, not a definitive diagnosis.
A5: C0S4 | B5: practice | C5: Pelvis Academy | D5: Associated-injury collection | E5: LO1 | F5: understand | G5: FALSE | H5: =COUNTIFS('Station Responses'!$F$2:$F$5000,"C0S4",'Station Responses'!$T$2:$T$5000,FALSE) | I5: =IFERROR(AVERAGEIFS('Station Responses'!$K$2:$K$5000,'Station Responses'!$F$2:$F$5000,"C0S4",'Station Responses'!$T$2:$T$5000,FALSE),"") | J5: =IFERROR(COUNTIFS('Station Responses'!$F$2:$F$5000,"C0S4",'Station Responses'!$T$2:$T$5000,FALSE,'Station Responses'!$K$2:$K$5000,0,'Station Responses'!$L$2:$L$5000,1)/COUNTIFS('Station Responses'!$F$2:$F$5000,"C0S4",'Station Responses'!$T$2:$T$5000,FALSE,'Station Responses'!$K$2:$K$5000,0),"") | K5: =IFERROR(AVERAGEIFS('Station Responses'!$K$2:$K$5000,'Station Responses'!$F$2:$F$5000,"C0S4",'Station Responses'!$T$2:$T$5000,FALSE,'Station Responses'!$S$2:$S$5000,"upper")-AVERAGEIFS('Station Responses'!$K$2:$K$5000,'Station Responses'!$F$2:$F$5000,"C0S4",'Station Responses'!$T$2:$T$5000,FALSE,'Station Responses'!$S$2:$S$5000,"lower"),"") | L5: =IFERROR(AVERAGEIFS('Station Responses'!$P$2:$P$5000,'Station Responses'!$F$2:$F$5000,"C0S4",'Station Responses'!$T$2:$T$5000,FALSE,'Station Responses'!$P$2:$P$5000,">0"),"") | M5: =IFERROR(COUNTIFS('Station Responses'!$F$2:$F$5000,"C0S4",'Station Responses'!$T$2:$T$5000,FALSE,'Station Responses'!$O$2:$O$5000,">0")/H5,"") | N5: =IF(H5<5,"too few answers",IF(I5<0.3,"very hard — review teaching or item",IF(I5>0.9,"very easy",IF(AND(K5<>"",K5<0.2),"low discrimination — review item","OK")))) | O5: Look beyond the pelvis; these percentages describe the supplied source cohort.
A6: C1S1 | B6: practice | C6: Red Alert | D6: Primary survey track | E6: LO2 | F6: apply | G6: FALSE | H6: =COUNTIFS('Station Responses'!$F$2:$F$5000,"C1S1",'Station Responses'!$T$2:$T$5000,FALSE) | I6: =IFERROR(AVERAGEIFS('Station Responses'!$K$2:$K$5000,'Station Responses'!$F$2:$F$5000,"C1S1",'Station Responses'!$T$2:$T$5000,FALSE),"") | J6: =IFERROR(COUNTIFS('Station Responses'!$F$2:$F$5000,"C1S1",'Station Responses'!$T$2:$T$5000,FALSE,'Station Responses'!$K$2:$K$5000,0,'Station Responses'!$L$2:$L$5000,1)/COUNTIFS('Station Responses'!$F$2:$F$5000,"C1S1",'Station Responses'!$T$2:$T$5000,FALSE,'Station Responses'!$K$2:$K$5000,0),"") | K6: =IFERROR(AVERAGEIFS('Station Responses'!$K$2:$K$5000,'Station Responses'!$F$2:$F$5000,"C1S1",'Station Responses'!$T$2:$T$5000,FALSE,'Station Responses'!$S$2:$S$5000,"upper")-AVERAGEIFS('Station Responses'!$K$2:$K$5000,'Station Responses'!$F$2:$F$5000,"C1S1",'Station Responses'!$T$2:$T$5000,FALSE,'Station Responses'!$S$2:$S$5000,"lower"),"") | L6: =IFERROR(AVERAGEIFS('Station Responses'!$P$2:$P$5000,'Station Responses'!$F$2:$F$5000,"C1S1",'Station Responses'!$T$2:$T$5000,FALSE,'Station Responses'!$P$2:$P$5000,">0"),"") | M6: =IFERROR(COUNTIFS('Station Responses'!$F$2:$F$5000,"C1S1",'Station Responses'!$T$2:$T$5000,FALSE,'Station Responses'!$O$2:$O$5000,">0")/H6,"") | N6: =IF(H6<5,"too few answers",IF(I6<0.3,"very hard — review teaching or item",IF(I6>0.9,"very easy",IF(AND(K6<>"",K6<0.2),"low discrimination — review item","OK")))) | O6: ABCDE priorities guide a team working in parallel.
A7: C1S2 | B7: practice | C7: Red Alert | D7: Shock bucket | E7: LO5 | F7: understand | G7: FALSE | H7: =COUNTIFS('Station Responses'!$F$2:$F$5000,"C1S2",'Station Responses'!$T$2:$T$5000,FALSE) | I7: =IFERROR(AVERAGEIFS('Station Responses'!$K$2:$K$5000,'Station Responses'!$F$2:$F$5000,"C1S2",'Station Responses'!$T$2:$T$5000,FALSE),"") | J7: =IFERROR(COUNTIFS('Station Responses'!$F$2:$F$5000,"C1S2",'Station Responses'!$T$2:$T$5000,FALSE,'Station Responses'!$K$2:$K$5000,0,'Station Responses'!$L$2:$L$5000,1)/COUNTIFS('Station Responses'!$F$2:$F$5000,"C1S2",'Station Responses'!$T$2:$T$5000,FALSE,'Station Responses'!$K$2:$K$5000,0),"") | K7: =IFERROR(AVERAGEIFS('Station Responses'!$K$2:$K$5000,'Station Responses'!$F$2:$F$5000,"C1S2",'Station Responses'!$T$2:$T$5000,FALSE,'Station Responses'!$S$2:$S$5000,"upper")-AVERAGEIFS('Station Responses'!$K$2:$K$5000,'Station Responses'!$F$2:$F$5000,"C1S2",'Station Responses'!$T$2:$T$5000,FALSE,'Station Responses'!$S$2:$S$5000,"lower"),"") | L7: =IFERROR(AVERAGEIFS('Station Responses'!$P$2:$P$5000,'Station Responses'!$F$2:$F$5000,"C1S2",'Station Responses'!$T$2:$T$5000,FALSE,'Station Responses'!$P$2:$P$5000,">0"),"") | M7: =IFERROR(COUNTIFS('Station Responses'!$F$2:$F$5000,"C1S2",'Station Responses'!$T$2:$T$5000,FALSE,'Station Responses'!$O$2:$O$5000,">0")/H7,"") | N7: =IF(H7<5,"too few answers",IF(I7<0.3,"very hard — review teaching or item",IF(I7>0.9,"very easy",IF(AND(K7<>"",K7<0.2),"low discrimination — review item","OK")))) | O7: Class III is a teaching estimate; trends and response matter more than a bucket.
A8: C1S3 | B8: practice | C8: Red Alert | D8: Build the resuscitation hand | E8: LO5;LO6 | F8: understand | G8: FALSE | H8: =COUNTIFS('Station Responses'!$F$2:$F$5000,"C1S3",'Station Responses'!$T$2:$T$5000,FALSE) | I8: =IFERROR(AVERAGEIFS('Station Responses'!$K$2:$K$5000,'Station Responses'!$F$2:$F$5000,"C1S3",'Station Responses'!$T$2:$T$5000,FALSE),"") | J8: =IFERROR(COUNTIFS('Station Responses'!$F$2:$F$5000,"C1S3",'Station Responses'!$T$2:$T$5000,FALSE,'Station Responses'!$K$2:$K$5000,0,'Station Responses'!$L$2:$L$5000,1)/COUNTIFS('Station Responses'!$F$2:$F$5000,"C1S3",'Station Responses'!$T$2:$T$5000,FALSE,'Station Responses'!$K$2:$K$5000,0),"") | K8: =IFERROR(AVERAGEIFS('Station Responses'!$K$2:$K$5000,'Station Responses'!$F$2:$F$5000,"C1S3",'Station Responses'!$T$2:$T$5000,FALSE,'Station Responses'!$S$2:$S$5000,"upper")-AVERAGEIFS('Station Responses'!$K$2:$K$5000,'Station Responses'!$F$2:$F$5000,"C1S3",'Station Responses'!$T$2:$T$5000,FALSE,'Station Responses'!$S$2:$S$5000,"lower"),"") | L8: =IFERROR(AVERAGEIFS('Station Responses'!$P$2:$P$5000,'Station Responses'!$F$2:$F$5000,"C1S3",'Station Responses'!$T$2:$T$5000,FALSE,'Station Responses'!$P$2:$P$5000,">0"),"") | M8: =IFERROR(COUNTIFS('Station Responses'!$F$2:$F$5000,"C1S3",'Station Responses'!$T$2:$T$5000,FALSE,'Station Responses'!$O$2:$O$5000,">0")/H8,"") | N8: =IF(H8<5,"too few answers",IF(I8<0.3,"very hard — review teaching or item",IF(I8>0.9,"very easy",IF(AND(K8<>"",K8<0.2),"low discrimination — review item","OK")))) | O8: Prepare access, tests, blood and stabilization while escalating.
A9: C1S4 | B9: practice | C9: Red Alert | D9: Binder workshop on screen | E9: LO6 | F9: apply | G9: FALSE | H9: =COUNTIFS('Station Responses'!$F$2:$F$5000,"C1S4",'Station Responses'!$T$2:$T$5000,FALSE) | I9: =IFERROR(AVERAGEIFS('Station Responses'!$K$2:$K$5000,'Station Responses'!$F$2:$F$5000,"C1S4",'Station Responses'!$T$2:$T$5000,FALSE),"") | J9: =IFERROR(COUNTIFS('Station Responses'!$F$2:$F$5000,"C1S4",'Station Responses'!$T$2:$T$5000,FALSE,'Station Responses'!$K$2:$K$5000,0,'Station Responses'!$L$2:$L$5000,1)/COUNTIFS('Station Responses'!$F$2:$F$5000,"C1S4",'Station Responses'!$T$2:$T$5000,FALSE,'Station Responses'!$K$2:$K$5000,0),"") | K9: =IFERROR(AVERAGEIFS('Station Responses'!$K$2:$K$5000,'Station Responses'!$F$2:$F$5000,"C1S4",'Station Responses'!$T$2:$T$5000,FALSE,'Station Responses'!$S$2:$S$5000,"upper")-AVERAGEIFS('Station Responses'!$K$2:$K$5000,'Station Responses'!$F$2:$F$5000,"C1S4",'Station Responses'!$T$2:$T$5000,FALSE,'Station Responses'!$S$2:$S$5000,"lower"),"") | L9: =IFERROR(AVERAGEIFS('Station Responses'!$P$2:$P$5000,'Station Responses'!$F$2:$F$5000,"C1S4",'Station Responses'!$T$2:$T$5000,FALSE,'Station Responses'!$P$2:$P$5000,">0"),"") | M9: =IFERROR(COUNTIFS('Station Responses'!$F$2:$F$5000,"C1S4",'Station Responses'!$T$2:$T$5000,FALSE,'Station Responses'!$O$2:$O$5000,">0")/H9,"") | N9: =IF(H9<5,"too few answers",IF(I9<0.3,"very hard — review teaching or item",IF(I9>0.9,"very easy",IF(AND(K9<>"",K9<0.2),"low discrimination — review item","OK")))) | O9: Binder for every suspected pelvic fracture: centred on the greater trochanters, snug (not loose, not over-tight), legs internally rotated with padding; remove within 24 h.
A10: C1S5 | B10: practice | C10: Red Alert | D10: Stabilization picture | E10: LO6 | F10: apply | G10: FALSE | H10: =COUNTIFS('Station Responses'!$F$2:$F$5000,"C1S5",'Station Responses'!$T$2:$T$5000,FALSE) | I10: =IFERROR(AVERAGEIFS('Station Responses'!$K$2:$K$5000,'Station Responses'!$F$2:$F$5000,"C1S5",'Station Responses'!$T$2:$T$5000,FALSE),"") | J10: =IFERROR(COUNTIFS('Station Responses'!$F$2:$F$5000,"C1S5",'Station Responses'!$T$2:$T$5000,FALSE,'Station Responses'!$K$2:$K$5000,0,'Station Responses'!$L$2:$L$5000,1)/COUNTIFS('Station Responses'!$F$2:$F$5000,"C1S5",'Station Responses'!$T$2:$T$5000,FALSE,'Station Responses'!$K$2:$K$5000,0),"") | K10: =IFERROR(AVERAGEIFS('Station Responses'!$K$2:$K$5000,'Station Responses'!$F$2:$F$5000,"C1S5",'Station Responses'!$T$2:$T$5000,FALSE,'Station Responses'!$S$2:$S$5000,"upper")-AVERAGEIFS('Station Responses'!$K$2:$K$5000,'Station Responses'!$F$2:$F$5000,"C1S5",'Station Responses'!$T$2:$T$5000,FALSE,'Station Responses'!$S$2:$S$5000,"lower"),"") | L10: =IFERROR(AVERAGEIFS('Station Responses'!$P$2:$P$5000,'Station Responses'!$F$2:$F$5000,"C1S5",'Station Responses'!$T$2:$T$5000,FALSE,'Station Responses'!$P$2:$P$5000,">0"),"") | M10: =IFERROR(COUNTIFS('Station Responses'!$F$2:$F$5000,"C1S5",'Station Responses'!$T$2:$T$5000,FALSE,'Station Responses'!$O$2:$O$5000,">0")/H10,"") | N10: =IF(H10<5,"too few answers",IF(I10<0.3,"very hard — review teaching or item",IF(I10>0.9,"very easy",IF(AND(K10<>"",K10<0.2),"low discrimination — review item","OK")))) | O10: Stabilization supports clot formation; it does not prove bleeding has stopped.
A11: C1S6 | B11: practice | C11: Red Alert | D11: Where is the blood? | E11: LO5 | F11: apply | G11: FALSE | H11: =COUNTIFS('Station Responses'!$F$2:$F$5000,"C1S6",'Station Responses'!$T$2:$T$5000,FALSE) | I11: =IFERROR(AVERAGEIFS('Station Responses'!$K$2:$K$5000,'Station Responses'!$F$2:$F$5000,"C1S6",'Station Responses'!$T$2:$T$5000,FALSE),"") | J11: =IFERROR(COUNTIFS('Station Responses'!$F$2:$F$5000,"C1S6",'Station Responses'!$T$2:$T$5000,FALSE,'Station Responses'!$K$2:$K$5000,0,'Station Responses'!$L$2:$L$5000,1)/COUNTIFS('Station Responses'!$F$2:$F$5000,"C1S6",'Station Responses'!$T$2:$T$5000,FALSE,'Station Responses'!$K$2:$K$5000,0),"") | K11: =IFERROR(AVERAGEIFS('Station Responses'!$K$2:$K$5000,'Station Responses'!$F$2:$F$5000,"C1S6",'Station Responses'!$T$2:$T$5000,FALSE,'Station Responses'!$S$2:$S$5000,"upper")-AVERAGEIFS('Station Responses'!$K$2:$K$5000,'Station Responses'!$F$2:$F$5000,"C1S6",'Station Responses'!$T$2:$T$5000,FALSE,'Station Responses'!$S$2:$S$5000,"lower"),"") | L11: =IFERROR(AVERAGEIFS('Station Responses'!$P$2:$P$5000,'Station Responses'!$F$2:$F$5000,"C1S6",'Station Responses'!$T$2:$T$5000,FALSE,'Station Responses'!$P$2:$P$5000,">0"),"") | M11: =IFERROR(COUNTIFS('Station Responses'!$F$2:$F$5000,"C1S6",'Station Responses'!$T$2:$T$5000,FALSE,'Station Responses'!$O$2:$O$5000,">0")/H11,"") | N11: =IF(H11<5,"too few answers",IF(I11<0.3,"very hard — review teaching or item",IF(I11>0.9,"very easy",IF(AND(K11<>"",K11<0.2),"low discrimination — review item","OK")))) | O11: Bleeding is 80% venous/bone and 20% arterial (superior gluteal most often). Angio-embolization finds an arterial source in only 10–15% and does not stop venous bleeding. 50–69% of unstable fractures need ≥4 U LPRC. Lactate ≥4: keep resuscitating; lactate <4: definitive fixation.
A12: C1S7 | B12: practice | C12: Red Alert | D12: Urgent SBAR | E12: LO7;LO5 | F12: apply | G12: FALSE | H12: =COUNTIFS('Station Responses'!$F$2:$F$5000,"C1S7",'Station Responses'!$T$2:$T$5000,FALSE) | I12: =IFERROR(AVERAGEIFS('Station Responses'!$K$2:$K$5000,'Station Responses'!$F$2:$F$5000,"C1S7",'Station Responses'!$T$2:$T$5000,FALSE),"") | J12: =IFERROR(COUNTIFS('Station Responses'!$F$2:$F$5000,"C1S7",'Station Responses'!$T$2:$T$5000,FALSE,'Station Responses'!$K$2:$K$5000,0,'Station Responses'!$L$2:$L$5000,1)/COUNTIFS('Station Responses'!$F$2:$F$5000,"C1S7",'Station Responses'!$T$2:$T$5000,FALSE,'Station Responses'!$K$2:$K$5000,0),"") | K12: =IFERROR(AVERAGEIFS('Station Responses'!$K$2:$K$5000,'Station Responses'!$F$2:$F$5000,"C1S7",'Station Responses'!$T$2:$T$5000,FALSE,'Station Responses'!$S$2:$S$5000,"upper")-AVERAGEIFS('Station Responses'!$K$2:$K$5000,'Station Responses'!$F$2:$F$5000,"C1S7",'Station Responses'!$T$2:$T$5000,FALSE,'Station Responses'!$S$2:$S$5000,"lower"),"") | L12: =IFERROR(AVERAGEIFS('Station Responses'!$P$2:$P$5000,'Station Responses'!$F$2:$F$5000,"C1S7",'Station Responses'!$T$2:$T$5000,FALSE,'Station Responses'!$P$2:$P$5000,">0"),"") | M12: =IFERROR(COUNTIFS('Station Responses'!$F$2:$F$5000,"C1S7",'Station Responses'!$T$2:$T$5000,FALSE,'Station Responses'!$O$2:$O$5000,">0")/H12,"") | N12: =IF(H12<5,"too few answers",IF(I12<0.3,"very hard — review teaching or item",IF(I12>0.9,"very easy",IF(AND(K12<>"",K12<0.2),"low discrimination — review item","OK")))) | O12: State physiology, response, uncertainty and an urgent request.
A13: C2S1 | B13: practice | C13: The Hidden Fracture | D13: Trauma-series films | E13: LO3 | F13: apply | G13: FALSE | H13: =COUNTIFS('Station Responses'!$F$2:$F$5000,"C2S1",'Station Responses'!$T$2:$T$5000,FALSE) | I13: =IFERROR(AVERAGEIFS('Station Responses'!$K$2:$K$5000,'Station Responses'!$F$2:$F$5000,"C2S1",'Station Responses'!$T$2:$T$5000,FALSE),"") | J13: =IFERROR(COUNTIFS('Station Responses'!$F$2:$F$5000,"C2S1",'Station Responses'!$T$2:$T$5000,FALSE,'Station Responses'!$K$2:$K$5000,0,'Station Responses'!$L$2:$L$5000,1)/COUNTIFS('Station Responses'!$F$2:$F$5000,"C2S1",'Station Responses'!$T$2:$T$5000,FALSE,'Station Responses'!$K$2:$K$5000,0),"") | K13: =IFERROR(AVERAGEIFS('Station Responses'!$K$2:$K$5000,'Station Responses'!$F$2:$F$5000,"C2S1",'Station Responses'!$T$2:$T$5000,FALSE,'Station Responses'!$S$2:$S$5000,"upper")-AVERAGEIFS('Station Responses'!$K$2:$K$5000,'Station Responses'!$F$2:$F$5000,"C2S1",'Station Responses'!$T$2:$T$5000,FALSE,'Station Responses'!$S$2:$S$5000,"lower"),"") | L13: =IFERROR(AVERAGEIFS('Station Responses'!$P$2:$P$5000,'Station Responses'!$F$2:$F$5000,"C2S1",'Station Responses'!$T$2:$T$5000,FALSE,'Station Responses'!$P$2:$P$5000,">0"),"") | M13: =IFERROR(COUNTIFS('Station Responses'!$F$2:$F$5000,"C2S1",'Station Responses'!$T$2:$T$5000,FALSE,'Station Responses'!$O$2:$O$5000,">0")/H13,"") | N13: =IF(H13<5,"too few answers",IF(I13<0.3,"very hard — review teaching or item",IF(I13>0.9,"very easy",IF(AND(K13<>"",K13<0.2),"low discrimination — review item","OK")))) | O13: Trauma series: C-spine lateral, chest AP and pelvis AP. The AP pelvis picks up about 90% of pelvic fractures; posterior injuries can still be missed.
A14: C2S2 | B14: practice | C14: The Hidden Fracture | D14: Read the ring | E14: LO3 | F14: apply | G14: FALSE | H14: =COUNTIFS('Station Responses'!$F$2:$F$5000,"C2S2",'Station Responses'!$T$2:$T$5000,FALSE) | I14: =IFERROR(AVERAGEIFS('Station Responses'!$K$2:$K$5000,'Station Responses'!$F$2:$F$5000,"C2S2",'Station Responses'!$T$2:$T$5000,FALSE),"") | J14: =IFERROR(COUNTIFS('Station Responses'!$F$2:$F$5000,"C2S2",'Station Responses'!$T$2:$T$5000,FALSE,'Station Responses'!$K$2:$K$5000,0,'Station Responses'!$L$2:$L$5000,1)/COUNTIFS('Station Responses'!$F$2:$F$5000,"C2S2",'Station Responses'!$T$2:$T$5000,FALSE,'Station Responses'!$K$2:$K$5000,0),"") | K14: =IFERROR(AVERAGEIFS('Station Responses'!$K$2:$K$5000,'Station Responses'!$F$2:$F$5000,"C2S2",'Station Responses'!$T$2:$T$5000,FALSE,'Station Responses'!$S$2:$S$5000,"upper")-AVERAGEIFS('Station Responses'!$K$2:$K$5000,'Station Responses'!$F$2:$F$5000,"C2S2",'Station Responses'!$T$2:$T$5000,FALSE,'Station Responses'!$S$2:$S$5000,"lower"),"") | L14: =IFERROR(AVERAGEIFS('Station Responses'!$P$2:$P$5000,'Station Responses'!$F$2:$F$5000,"C2S2",'Station Responses'!$T$2:$T$5000,FALSE,'Station Responses'!$P$2:$P$5000,">0"),"") | M14: =IFERROR(COUNTIFS('Station Responses'!$F$2:$F$5000,"C2S2",'Station Responses'!$T$2:$T$5000,FALSE,'Station Responses'!$O$2:$O$5000,">0")/H14,"") | N14: =IF(H14<5,"too few answers",IF(I14<0.3,"very hard — review teaching or item",IF(I14>0.9,"very easy",IF(AND(K14<>"",K14<0.2),"low discrimination — review item","OK")))) | O14: Read the AP pelvis systematically around the whole ring and both hips. Four rami broken (straddle fracture) means: suspect a posterior ring injury too.
A15: C2S3 | B15: practice | C15: The Hidden Fracture | D15: Beam and view pairs | E15: LO3 | F15: understand | G15: FALSE | H15: =COUNTIFS('Station Responses'!$F$2:$F$5000,"C2S3",'Station Responses'!$T$2:$T$5000,FALSE) | I15: =IFERROR(AVERAGEIFS('Station Responses'!$K$2:$K$5000,'Station Responses'!$F$2:$F$5000,"C2S3",'Station Responses'!$T$2:$T$5000,FALSE),"") | J15: =IFERROR(COUNTIFS('Station Responses'!$F$2:$F$5000,"C2S3",'Station Responses'!$T$2:$T$5000,FALSE,'Station Responses'!$K$2:$K$5000,0,'Station Responses'!$L$2:$L$5000,1)/COUNTIFS('Station Responses'!$F$2:$F$5000,"C2S3",'Station Responses'!$T$2:$T$5000,FALSE,'Station Responses'!$K$2:$K$5000,0),"") | K15: =IFERROR(AVERAGEIFS('Station Responses'!$K$2:$K$5000,'Station Responses'!$F$2:$F$5000,"C2S3",'Station Responses'!$T$2:$T$5000,FALSE,'Station Responses'!$S$2:$S$5000,"upper")-AVERAGEIFS('Station Responses'!$K$2:$K$5000,'Station Responses'!$F$2:$F$5000,"C2S3",'Station Responses'!$T$2:$T$5000,FALSE,'Station Responses'!$S$2:$S$5000,"lower"),"") | L15: =IFERROR(AVERAGEIFS('Station Responses'!$P$2:$P$5000,'Station Responses'!$F$2:$F$5000,"C2S3",'Station Responses'!$T$2:$T$5000,FALSE,'Station Responses'!$P$2:$P$5000,">0"),"") | M15: =IFERROR(COUNTIFS('Station Responses'!$F$2:$F$5000,"C2S3",'Station Responses'!$T$2:$T$5000,FALSE,'Station Responses'!$O$2:$O$5000,">0")/H15,"") | N15: =IF(H15<5,"too few answers",IF(I15<0.3,"very hard — review teaching or item",IF(I15>0.9,"very easy",IF(AND(K15<>"",K15<0.2),"low discrimination — review item","OK")))) | O15: Inlet assesses AP displacement; outlet assesses vertical displacement.
A16: C2S4 | B16: practice | C16: The Hidden Fracture | D16: Stability clue sort | E16: LO3 | F16: understand | G16: FALSE | H16: =COUNTIFS('Station Responses'!$F$2:$F$5000,"C2S4",'Station Responses'!$T$2:$T$5000,FALSE) | I16: =IFERROR(AVERAGEIFS('Station Responses'!$K$2:$K$5000,'Station Responses'!$F$2:$F$5000,"C2S4",'Station Responses'!$T$2:$T$5000,FALSE),"") | J16: =IFERROR(COUNTIFS('Station Responses'!$F$2:$F$5000,"C2S4",'Station Responses'!$T$2:$T$5000,FALSE,'Station Responses'!$K$2:$K$5000,0,'Station Responses'!$L$2:$L$5000,1)/COUNTIFS('Station Responses'!$F$2:$F$5000,"C2S4",'Station Responses'!$T$2:$T$5000,FALSE,'Station Responses'!$K$2:$K$5000,0),"") | K16: =IFERROR(AVERAGEIFS('Station Responses'!$K$2:$K$5000,'Station Responses'!$F$2:$F$5000,"C2S4",'Station Responses'!$T$2:$T$5000,FALSE,'Station Responses'!$S$2:$S$5000,"upper")-AVERAGEIFS('Station Responses'!$K$2:$K$5000,'Station Responses'!$F$2:$F$5000,"C2S4",'Station Responses'!$T$2:$T$5000,FALSE,'Station Responses'!$S$2:$S$5000,"lower"),"") | L16: =IFERROR(AVERAGEIFS('Station Responses'!$P$2:$P$5000,'Station Responses'!$F$2:$F$5000,"C2S4",'Station Responses'!$T$2:$T$5000,FALSE,'Station Responses'!$P$2:$P$5000,">0"),"") | M16: =IFERROR(COUNTIFS('Station Responses'!$F$2:$F$5000,"C2S4",'Station Responses'!$T$2:$T$5000,FALSE,'Station Responses'!$O$2:$O$5000,">0")/H16,"") | N16: =IF(H16<5,"too few answers",IF(I16<0.3,"very hard — review teaching or item",IF(I16>0.9,"very easy",IF(AND(K16<>"",K16<0.2),"low discrimination — review item","OK")))) | O16: Normal physiology is not proof of mechanical stability.
A17: C2S5 | B17: practice | C17: The Hidden Fracture | D17: Safe CT transfer | E17: LO3;LO5 | F17: apply | G17: FALSE | H17: =COUNTIFS('Station Responses'!$F$2:$F$5000,"C2S5",'Station Responses'!$T$2:$T$5000,FALSE) | I17: =IFERROR(AVERAGEIFS('Station Responses'!$K$2:$K$5000,'Station Responses'!$F$2:$F$5000,"C2S5",'Station Responses'!$T$2:$T$5000,FALSE),"") | J17: =IFERROR(COUNTIFS('Station Responses'!$F$2:$F$5000,"C2S5",'Station Responses'!$T$2:$T$5000,FALSE,'Station Responses'!$K$2:$K$5000,0,'Station Responses'!$L$2:$L$5000,1)/COUNTIFS('Station Responses'!$F$2:$F$5000,"C2S5",'Station Responses'!$T$2:$T$5000,FALSE,'Station Responses'!$K$2:$K$5000,0),"") | K17: =IFERROR(AVERAGEIFS('Station Responses'!$K$2:$K$5000,'Station Responses'!$F$2:$F$5000,"C2S5",'Station Responses'!$T$2:$T$5000,FALSE,'Station Responses'!$S$2:$S$5000,"upper")-AVERAGEIFS('Station Responses'!$K$2:$K$5000,'Station Responses'!$F$2:$F$5000,"C2S5",'Station Responses'!$T$2:$T$5000,FALSE,'Station Responses'!$S$2:$S$5000,"lower"),"") | L17: =IFERROR(AVERAGEIFS('Station Responses'!$P$2:$P$5000,'Station Responses'!$F$2:$F$5000,"C2S5",'Station Responses'!$T$2:$T$5000,FALSE,'Station Responses'!$P$2:$P$5000,">0"),"") | M17: =IFERROR(COUNTIFS('Station Responses'!$F$2:$F$5000,"C2S5",'Station Responses'!$T$2:$T$5000,FALSE,'Station Responses'!$O$2:$O$5000,">0")/H17,"") | N17: =IF(H17<5,"too few answers",IF(I17<0.3,"very hard — review teaching or item",IF(I17>0.9,"very easy",IF(AND(K17<>"",K17<0.2),"low discrimination — review item","OK")))) | O17: Reassess physiology and capability before CT, while treatment continues.
A18: C2S6 | B18: practice | C18: The Hidden Fracture | D18: Pattern and urgency | E18: LO1;LO3;LO7 | F18: apply | G18: FALSE | H18: =COUNTIFS('Station Responses'!$F$2:$F$5000,"C2S6",'Station Responses'!$T$2:$T$5000,FALSE) | I18: =IFERROR(AVERAGEIFS('Station Responses'!$K$2:$K$5000,'Station Responses'!$F$2:$F$5000,"C2S6",'Station Responses'!$T$2:$T$5000,FALSE),"") | J18: =IFERROR(COUNTIFS('Station Responses'!$F$2:$F$5000,"C2S6",'Station Responses'!$T$2:$T$5000,FALSE,'Station Responses'!$K$2:$K$5000,0,'Station Responses'!$L$2:$L$5000,1)/COUNTIFS('Station Responses'!$F$2:$F$5000,"C2S6",'Station Responses'!$T$2:$T$5000,FALSE,'Station Responses'!$K$2:$K$5000,0),"") | K18: =IFERROR(AVERAGEIFS('Station Responses'!$K$2:$K$5000,'Station Responses'!$F$2:$F$5000,"C2S6",'Station Responses'!$T$2:$T$5000,FALSE,'Station Responses'!$S$2:$S$5000,"upper")-AVERAGEIFS('Station Responses'!$K$2:$K$5000,'Station Responses'!$F$2:$F$5000,"C2S6",'Station Responses'!$T$2:$T$5000,FALSE,'Station Responses'!$S$2:$S$5000,"lower"),"") | L18: =IFERROR(AVERAGEIFS('Station Responses'!$P$2:$P$5000,'Station Responses'!$F$2:$F$5000,"C2S6",'Station Responses'!$T$2:$T$5000,FALSE,'Station Responses'!$P$2:$P$5000,">0"),"") | M18: =IFERROR(COUNTIFS('Station Responses'!$F$2:$F$5000,"C2S6",'Station Responses'!$T$2:$T$5000,FALSE,'Station Responses'!$O$2:$O$5000,">0")/H18,"") | N18: =IF(H18<5,"too few answers",IF(I18<0.3,"very hard — review teaching or item",IF(I18>0.9,"very easy",IF(AND(K18<>"",K18<0.2),"low discrimination — review item","OK")))) | O18: Source-reported hip dislocation is an orthopaedic urgency; escalate, do not reduce independently.
A19: C3S1 | B19: practice | C19: Danger Down Below | D19: AMPLE collection | E19: LO2 | F19: apply | G19: FALSE | H19: =COUNTIFS('Station Responses'!$F$2:$F$5000,"C3S1",'Station Responses'!$T$2:$T$5000,FALSE) | I19: =IFERROR(AVERAGEIFS('Station Responses'!$K$2:$K$5000,'Station Responses'!$F$2:$F$5000,"C3S1",'Station Responses'!$T$2:$T$5000,FALSE),"") | J19: =IFERROR(COUNTIFS('Station Responses'!$F$2:$F$5000,"C3S1",'Station Responses'!$T$2:$T$5000,FALSE,'Station Responses'!$K$2:$K$5000,0,'Station Responses'!$L$2:$L$5000,1)/COUNTIFS('Station Responses'!$F$2:$F$5000,"C3S1",'Station Responses'!$T$2:$T$5000,FALSE,'Station Responses'!$K$2:$K$5000,0),"") | K19: =IFERROR(AVERAGEIFS('Station Responses'!$K$2:$K$5000,'Station Responses'!$F$2:$F$5000,"C3S1",'Station Responses'!$T$2:$T$5000,FALSE,'Station Responses'!$S$2:$S$5000,"upper")-AVERAGEIFS('Station Responses'!$K$2:$K$5000,'Station Responses'!$F$2:$F$5000,"C3S1",'Station Responses'!$T$2:$T$5000,FALSE,'Station Responses'!$S$2:$S$5000,"lower"),"") | L19: =IFERROR(AVERAGEIFS('Station Responses'!$P$2:$P$5000,'Station Responses'!$F$2:$F$5000,"C3S1",'Station Responses'!$T$2:$T$5000,FALSE,'Station Responses'!$P$2:$P$5000,">0"),"") | M19: =IFERROR(COUNTIFS('Station Responses'!$F$2:$F$5000,"C3S1",'Station Responses'!$T$2:$T$5000,FALSE,'Station Responses'!$O$2:$O$5000,">0")/H19,"") | N19: =IF(H19<5,"too few answers",IF(I19<0.3,"very hard — review teaching or item",IF(I19>0.9,"very easy",IF(AND(K19<>"",K19<0.2),"low discrimination — review item","OK")))) | O19: Gather AMPLE without delaying resuscitation.
A20: C3S2 | B20: practice | C20: Danger Down Below | D20: Sensitive examination clues | E20: LO2;LO4 | F20: understand | G20: FALSE | H20: =COUNTIFS('Station Responses'!$F$2:$F$5000,"C3S2",'Station Responses'!$T$2:$T$5000,FALSE) | I20: =IFERROR(AVERAGEIFS('Station Responses'!$K$2:$K$5000,'Station Responses'!$F$2:$F$5000,"C3S2",'Station Responses'!$T$2:$T$5000,FALSE),"") | J20: =IFERROR(COUNTIFS('Station Responses'!$F$2:$F$5000,"C3S2",'Station Responses'!$T$2:$T$5000,FALSE,'Station Responses'!$K$2:$K$5000,0,'Station Responses'!$L$2:$L$5000,1)/COUNTIFS('Station Responses'!$F$2:$F$5000,"C3S2",'Station Responses'!$T$2:$T$5000,FALSE,'Station Responses'!$K$2:$K$5000,0),"") | K20: =IFERROR(AVERAGEIFS('Station Responses'!$K$2:$K$5000,'Station Responses'!$F$2:$F$5000,"C3S2",'Station Responses'!$T$2:$T$5000,FALSE,'Station Responses'!$S$2:$S$5000,"upper")-AVERAGEIFS('Station Responses'!$K$2:$K$5000,'Station Responses'!$F$2:$F$5000,"C3S2",'Station Responses'!$T$2:$T$5000,FALSE,'Station Responses'!$S$2:$S$5000,"lower"),"") | L20: =IFERROR(AVERAGEIFS('Station Responses'!$P$2:$P$5000,'Station Responses'!$F$2:$F$5000,"C3S2",'Station Responses'!$T$2:$T$5000,FALSE,'Station Responses'!$P$2:$P$5000,">0"),"") | M20: =IFERROR(COUNTIFS('Station Responses'!$F$2:$F$5000,"C3S2",'Station Responses'!$T$2:$T$5000,FALSE,'Station Responses'!$O$2:$O$5000,">0")/H20,"") | N20: =IF(H20<5,"too few answers",IF(I20<0.3,"very hard — review teaching or item",IF(I20>0.9,"very easy",IF(AND(K20<>"",K20<0.2),"low discrimination — review item","OK")))) | O20: Examine the perineum with consent and a chaperone: blood at the meatus or a high-riding prostate on PR suggests urethral injury; blood on PR or PV means an open (internal) pelvic fracture until proven otherwise.
A21: C3S3 | B21: practice | C21: Danger Down Below | D21: Compression-test safety | E21: LO2 | F21: apply | G21: FALSE | H21: =COUNTIFS('Station Responses'!$F$2:$F$5000,"C3S3",'Station Responses'!$T$2:$T$5000,FALSE) | I21: =IFERROR(AVERAGEIFS('Station Responses'!$K$2:$K$5000,'Station Responses'!$F$2:$F$5000,"C3S3",'Station Responses'!$T$2:$T$5000,FALSE),"") | J21: =IFERROR(COUNTIFS('Station Responses'!$F$2:$F$5000,"C3S3",'Station Responses'!$T$2:$T$5000,FALSE,'Station Responses'!$K$2:$K$5000,0,'Station Responses'!$L$2:$L$5000,1)/COUNTIFS('Station Responses'!$F$2:$F$5000,"C3S3",'Station Responses'!$T$2:$T$5000,FALSE,'Station Responses'!$K$2:$K$5000,0),"") | K21: =IFERROR(AVERAGEIFS('Station Responses'!$K$2:$K$5000,'Station Responses'!$F$2:$F$5000,"C3S3",'Station Responses'!$T$2:$T$5000,FALSE,'Station Responses'!$S$2:$S$5000,"upper")-AVERAGEIFS('Station Responses'!$K$2:$K$5000,'Station Responses'!$F$2:$F$5000,"C3S3",'Station Responses'!$T$2:$T$5000,FALSE,'Station Responses'!$S$2:$S$5000,"lower"),"") | L21: =IFERROR(AVERAGEIFS('Station Responses'!$P$2:$P$5000,'Station Responses'!$F$2:$F$5000,"C3S3",'Station Responses'!$T$2:$T$5000,FALSE,'Station Responses'!$P$2:$P$5000,">0"),"") | M21: =IFERROR(COUNTIFS('Station Responses'!$F$2:$F$5000,"C3S3",'Station Responses'!$T$2:$T$5000,FALSE,'Station Responses'!$O$2:$O$5000,">0")/H21,"") | N21: =IF(H21<5,"too few answers",IF(I21<0.3,"very hard — review teaching or item",IF(I21>0.9,"very easy",IF(AND(K21<>"",K21<0.2),"low discrimination — review item","OK")))) | O21: Pelvic compression test = 3 gentle manoeuvres, done once only. Do not do it in an unstable patient, and stop after the first positive step.
A22: C3S4 | B22: practice | C22: Danger Down Below | D22: Open, closed or degloving? | E22: LO4 | F22: understand | G22: FALSE | H22: =COUNTIFS('Station Responses'!$F$2:$F$5000,"C3S4",'Station Responses'!$T$2:$T$5000,FALSE) | I22: =IFERROR(AVERAGEIFS('Station Responses'!$K$2:$K$5000,'Station Responses'!$F$2:$F$5000,"C3S4",'Station Responses'!$T$2:$T$5000,FALSE),"") | J22: =IFERROR(COUNTIFS('Station Responses'!$F$2:$F$5000,"C3S4",'Station Responses'!$T$2:$T$5000,FALSE,'Station Responses'!$K$2:$K$5000,0,'Station Responses'!$L$2:$L$5000,1)/COUNTIFS('Station Responses'!$F$2:$F$5000,"C3S4",'Station Responses'!$T$2:$T$5000,FALSE,'Station Responses'!$K$2:$K$5000,0),"") | K22: =IFERROR(AVERAGEIFS('Station Responses'!$K$2:$K$5000,'Station Responses'!$F$2:$F$5000,"C3S4",'Station Responses'!$T$2:$T$5000,FALSE,'Station Responses'!$S$2:$S$5000,"upper")-AVERAGEIFS('Station Responses'!$K$2:$K$5000,'Station Responses'!$F$2:$F$5000,"C3S4",'Station Responses'!$T$2:$T$5000,FALSE,'Station Responses'!$S$2:$S$5000,"lower"),"") | L22: =IFERROR(AVERAGEIFS('Station Responses'!$P$2:$P$5000,'Station Responses'!$F$2:$F$5000,"C3S4",'Station Responses'!$T$2:$T$5000,FALSE,'Station Responses'!$P$2:$P$5000,">0"),"") | M22: =IFERROR(COUNTIFS('Station Responses'!$F$2:$F$5000,"C3S4",'Station Responses'!$T$2:$T$5000,FALSE,'Station Responses'!$O$2:$O$5000,">0")/H22,"") | N22: =IF(H22<5,"too few answers",IF(I22<0.3,"very hard — review teaching or item",IF(I22>0.9,"very easy",IF(AND(K22<>"",K22<0.2),"low discrimination — review item","OK")))) | O22: Open = a wound that communicates with the fracture: external (perineal wound, fat globules or bone in the wound) or internal (blood PR/PV). Mortality of open pelvic fracture is 30–50%.
A23: C3S5 | B23: practice | C23: Danger Down Below | D23: GU danger cards | E23: LO2;LO5 | F23: apply | G23: FALSE | H23: =COUNTIFS('Station Responses'!$F$2:$F$5000,"C3S5",'Station Responses'!$T$2:$T$5000,FALSE) | I23: =IFERROR(AVERAGEIFS('Station Responses'!$K$2:$K$5000,'Station Responses'!$F$2:$F$5000,"C3S5",'Station Responses'!$T$2:$T$5000,FALSE),"") | J23: =IFERROR(COUNTIFS('Station Responses'!$F$2:$F$5000,"C3S5",'Station Responses'!$T$2:$T$5000,FALSE,'Station Responses'!$K$2:$K$5000,0,'Station Responses'!$L$2:$L$5000,1)/COUNTIFS('Station Responses'!$F$2:$F$5000,"C3S5",'Station Responses'!$T$2:$T$5000,FALSE,'Station Responses'!$K$2:$K$5000,0),"") | K23: =IFERROR(AVERAGEIFS('Station Responses'!$K$2:$K$5000,'Station Responses'!$F$2:$F$5000,"C3S5",'Station Responses'!$T$2:$T$5000,FALSE,'Station Responses'!$S$2:$S$5000,"upper")-AVERAGEIFS('Station Responses'!$K$2:$K$5000,'Station Responses'!$F$2:$F$5000,"C3S5",'Station Responses'!$T$2:$T$5000,FALSE,'Station Responses'!$S$2:$S$5000,"lower"),"") | L23: =IFERROR(AVERAGEIFS('Station Responses'!$P$2:$P$5000,'Station Responses'!$F$2:$F$5000,"C3S5",'Station Responses'!$T$2:$T$5000,FALSE,'Station Responses'!$P$2:$P$5000,">0"),"") | M23: =IFERROR(COUNTIFS('Station Responses'!$F$2:$F$5000,"C3S5",'Station Responses'!$T$2:$T$5000,FALSE,'Station Responses'!$O$2:$O$5000,">0")/H23,"") | N23: =IF(H23<5,"too few answers",IF(I23<0.3,"very hard — review teaching or item",IF(I23>0.9,"very easy",IF(AND(K23<>"",K23<0.2),"low discrimination — review item","OK")))) | O23: No blind Foley with meatal bleeding: ask the senior/urology team for assessment.
A24: C3S6 | B24: practice | C24: Danger Down Below | D24: Open-fracture source bundle | E24: LO4;LO5 | F24: understand | G24: FALSE | H24: =COUNTIFS('Station Responses'!$F$2:$F$5000,"C3S6",'Station Responses'!$T$2:$T$5000,FALSE) | I24: =IFERROR(AVERAGEIFS('Station Responses'!$K$2:$K$5000,'Station Responses'!$F$2:$F$5000,"C3S6",'Station Responses'!$T$2:$T$5000,FALSE),"") | J24: =IFERROR(COUNTIFS('Station Responses'!$F$2:$F$5000,"C3S6",'Station Responses'!$T$2:$T$5000,FALSE,'Station Responses'!$K$2:$K$5000,0,'Station Responses'!$L$2:$L$5000,1)/COUNTIFS('Station Responses'!$F$2:$F$5000,"C3S6",'Station Responses'!$T$2:$T$5000,FALSE,'Station Responses'!$K$2:$K$5000,0),"") | K24: =IFERROR(AVERAGEIFS('Station Responses'!$K$2:$K$5000,'Station Responses'!$F$2:$F$5000,"C3S6",'Station Responses'!$T$2:$T$5000,FALSE,'Station Responses'!$S$2:$S$5000,"upper")-AVERAGEIFS('Station Responses'!$K$2:$K$5000,'Station Responses'!$F$2:$F$5000,"C3S6",'Station Responses'!$T$2:$T$5000,FALSE,'Station Responses'!$S$2:$S$5000,"lower"),"") | L24: =IFERROR(AVERAGEIFS('Station Responses'!$P$2:$P$5000,'Station Responses'!$F$2:$F$5000,"C3S6",'Station Responses'!$T$2:$T$5000,FALSE,'Station Responses'!$P$2:$P$5000,">0"),"") | M24: =IFERROR(COUNTIFS('Station Responses'!$F$2:$F$5000,"C3S6",'Station Responses'!$T$2:$T$5000,FALSE,'Station Responses'!$O$2:$O$5000,">0")/H24,"") | N24: =IF(H24<5,"too few answers",IF(I24<0.3,"very hard — review teaching or item",IF(I24>0.9,"very easy",IF(AND(K24<>"",K24<0.2),"low discrimination — review item","OK")))) | O24: Open pelvic fracture: IV antibiotics by Gustilo grade within 3 h, tetanus prophylaxis and urgent surgical debridement. Check allergy, weight and kidney function before prescribing.
A25: C3S7 | B25: practice | C25: Danger Down Below | D25: Three-team handover | E25: LO7;LO4;LO5 | F25: apply | G25: FALSE | H25: =COUNTIFS('Station Responses'!$F$2:$F$5000,"C3S7",'Station Responses'!$T$2:$T$5000,FALSE) | I25: =IFERROR(AVERAGEIFS('Station Responses'!$K$2:$K$5000,'Station Responses'!$F$2:$F$5000,"C3S7",'Station Responses'!$T$2:$T$5000,FALSE),"") | J25: =IFERROR(COUNTIFS('Station Responses'!$F$2:$F$5000,"C3S7",'Station Responses'!$T$2:$T$5000,FALSE,'Station Responses'!$K$2:$K$5000,0,'Station Responses'!$L$2:$L$5000,1)/COUNTIFS('Station Responses'!$F$2:$F$5000,"C3S7",'Station Responses'!$T$2:$T$5000,FALSE,'Station Responses'!$K$2:$K$5000,0),"") | K25: =IFERROR(AVERAGEIFS('Station Responses'!$K$2:$K$5000,'Station Responses'!$F$2:$F$5000,"C3S7",'Station Responses'!$T$2:$T$5000,FALSE,'Station Responses'!$S$2:$S$5000,"upper")-AVERAGEIFS('Station Responses'!$K$2:$K$5000,'Station Responses'!$F$2:$F$5000,"C3S7",'Station Responses'!$T$2:$T$5000,FALSE,'Station Responses'!$S$2:$S$5000,"lower"),"") | L25: =IFERROR(AVERAGEIFS('Station Responses'!$P$2:$P$5000,'Station Responses'!$F$2:$F$5000,"C3S7",'Station Responses'!$T$2:$T$5000,FALSE,'Station Responses'!$P$2:$P$5000,">0"),"") | M25: =IFERROR(COUNTIFS('Station Responses'!$F$2:$F$5000,"C3S7",'Station Responses'!$T$2:$T$5000,FALSE,'Station Responses'!$O$2:$O$5000,">0")/H25,"") | N25: =IF(H25<5,"too few answers",IF(I25<0.3,"very hard — review teaching or item",IF(I25>0.9,"very easy",IF(AND(K25<>"",K25<0.2),"low discrimination — review item","OK")))) | O25: General surgery, orthopaedics and urology coordinate; double set-up is senior-led.
A26: C0B1 | B26: boss review | C26: Pelvis Academy | D26: Boss recall: Force detective | E26: LO1 | F26: understand | G26: FALSE | H26: =COUNTIFS('Station Responses'!$F$2:$F$5000,"C0B1",'Station Responses'!$T$2:$T$5000,FALSE) | I26: =IFERROR(AVERAGEIFS('Station Responses'!$K$2:$K$5000,'Station Responses'!$F$2:$F$5000,"C0B1",'Station Responses'!$T$2:$T$5000,FALSE),"") | J26: =IFERROR(COUNTIFS('Station Responses'!$F$2:$F$5000,"C0B1",'Station Responses'!$T$2:$T$5000,FALSE,'Station Responses'!$K$2:$K$5000,0,'Station Responses'!$L$2:$L$5000,1)/COUNTIFS('Station Responses'!$F$2:$F$5000,"C0B1",'Station Responses'!$T$2:$T$5000,FALSE,'Station Responses'!$K$2:$K$5000,0),"") | K26: =IFERROR(AVERAGEIFS('Station Responses'!$K$2:$K$5000,'Station Responses'!$F$2:$F$5000,"C0B1",'Station Responses'!$T$2:$T$5000,FALSE,'Station Responses'!$S$2:$S$5000,"upper")-AVERAGEIFS('Station Responses'!$K$2:$K$5000,'Station Responses'!$F$2:$F$5000,"C0B1",'Station Responses'!$T$2:$T$5000,FALSE,'Station Responses'!$S$2:$S$5000,"lower"),"") | L26: =IFERROR(AVERAGEIFS('Station Responses'!$P$2:$P$5000,'Station Responses'!$F$2:$F$5000,"C0B1",'Station Responses'!$T$2:$T$5000,FALSE,'Station Responses'!$P$2:$P$5000,">0"),"") | M26: =IFERROR(COUNTIFS('Station Responses'!$F$2:$F$5000,"C0B1",'Station Responses'!$T$2:$T$5000,FALSE,'Station Responses'!$O$2:$O$5000,">0")/H26,"") | N26: =IF(H26<5,"too few answers",IF(I26<0.3,"very hard — review teaching or item",IF(I26>0.9,"very easy",IF(AND(K26<>"",K26<0.2),"low discrimination — review item","OK")))) | O26: Mechanism suggests a pattern, not a definitive diagnosis.
A27: C0B2 | B27: boss review | C27: Pelvis Academy | D27: Boss recall: Ligaments and their jobs | E27: LO1 | F27: understand | G27: FALSE | H27: =COUNTIFS('Station Responses'!$F$2:$F$5000,"C0B2",'Station Responses'!$T$2:$T$5000,FALSE) | I27: =IFERROR(AVERAGEIFS('Station Responses'!$K$2:$K$5000,'Station Responses'!$F$2:$F$5000,"C0B2",'Station Responses'!$T$2:$T$5000,FALSE),"") | J27: =IFERROR(COUNTIFS('Station Responses'!$F$2:$F$5000,"C0B2",'Station Responses'!$T$2:$T$5000,FALSE,'Station Responses'!$K$2:$K$5000,0,'Station Responses'!$L$2:$L$5000,1)/COUNTIFS('Station Responses'!$F$2:$F$5000,"C0B2",'Station Responses'!$T$2:$T$5000,FALSE,'Station Responses'!$K$2:$K$5000,0),"") | K27: =IFERROR(AVERAGEIFS('Station Responses'!$K$2:$K$5000,'Station Responses'!$F$2:$F$5000,"C0B2",'Station Responses'!$T$2:$T$5000,FALSE,'Station Responses'!$S$2:$S$5000,"upper")-AVERAGEIFS('Station Responses'!$K$2:$K$5000,'Station Responses'!$F$2:$F$5000,"C0B2",'Station Responses'!$T$2:$T$5000,FALSE,'Station Responses'!$S$2:$S$5000,"lower"),"") | L27: =IFERROR(AVERAGEIFS('Station Responses'!$P$2:$P$5000,'Station Responses'!$F$2:$F$5000,"C0B2",'Station Responses'!$T$2:$T$5000,FALSE,'Station Responses'!$P$2:$P$5000,">0"),"") | M27: =IFERROR(COUNTIFS('Station Responses'!$F$2:$F$5000,"C0B2",'Station Responses'!$T$2:$T$5000,FALSE,'Station Responses'!$O$2:$O$5000,">0")/H27,"") | N27: =IF(H27<5,"too few answers",IF(I27<0.3,"very hard — review teaching or item",IF(I27>0.9,"very easy",IF(AND(K27<>"",K27<0.2),"low discrimination — review item","OK")))) | O27: Ligament disruption explains instability clues.
A28: C0B3 | B28: boss review | C28: Pelvis Academy | D28: Boss recall: Associated-injury collection | E28: LO1 | F28: understand | G28: FALSE | H28: =COUNTIFS('Station Responses'!$F$2:$F$5000,"C0B3",'Station Responses'!$T$2:$T$5000,FALSE) | I28: =IFERROR(AVERAGEIFS('Station Responses'!$K$2:$K$5000,'Station Responses'!$F$2:$F$5000,"C0B3",'Station Responses'!$T$2:$T$5000,FALSE),"") | J28: =IFERROR(COUNTIFS('Station Responses'!$F$2:$F$5000,"C0B3",'Station Responses'!$T$2:$T$5000,FALSE,'Station Responses'!$K$2:$K$5000,0,'Station Responses'!$L$2:$L$5000,1)/COUNTIFS('Station Responses'!$F$2:$F$5000,"C0B3",'Station Responses'!$T$2:$T$5000,FALSE,'Station Responses'!$K$2:$K$5000,0),"") | K28: =IFERROR(AVERAGEIFS('Station Responses'!$K$2:$K$5000,'Station Responses'!$F$2:$F$5000,"C0B3",'Station Responses'!$T$2:$T$5000,FALSE,'Station Responses'!$S$2:$S$5000,"upper")-AVERAGEIFS('Station Responses'!$K$2:$K$5000,'Station Responses'!$F$2:$F$5000,"C0B3",'Station Responses'!$T$2:$T$5000,FALSE,'Station Responses'!$S$2:$S$5000,"lower"),"") | L28: =IFERROR(AVERAGEIFS('Station Responses'!$P$2:$P$5000,'Station Responses'!$F$2:$F$5000,"C0B3",'Station Responses'!$T$2:$T$5000,FALSE,'Station Responses'!$P$2:$P$5000,">0"),"") | M28: =IFERROR(COUNTIFS('Station Responses'!$F$2:$F$5000,"C0B3",'Station Responses'!$T$2:$T$5000,FALSE,'Station Responses'!$O$2:$O$5000,">0")/H28,"") | N28: =IF(H28<5,"too few answers",IF(I28<0.3,"very hard — review teaching or item",IF(I28>0.9,"very easy",IF(AND(K28<>"",K28<0.2),"low discrimination — review item","OK")))) | O28: Look beyond the pelvis; these percentages describe the supplied source cohort.
A29: C1B1 | B29: boss review | C29: Red Alert | D29: Boss recall: Shock bucket | E29: LO5 | F29: understand | G29: FALSE | H29: =COUNTIFS('Station Responses'!$F$2:$F$5000,"C1B1",'Station Responses'!$T$2:$T$5000,FALSE) | I29: =IFERROR(AVERAGEIFS('Station Responses'!$K$2:$K$5000,'Station Responses'!$F$2:$F$5000,"C1B1",'Station Responses'!$T$2:$T$5000,FALSE),"") | J29: =IFERROR(COUNTIFS('Station Responses'!$F$2:$F$5000,"C1B1",'Station Responses'!$T$2:$T$5000,FALSE,'Station Responses'!$K$2:$K$5000,0,'Station Responses'!$L$2:$L$5000,1)/COUNTIFS('Station Responses'!$F$2:$F$5000,"C1B1",'Station Responses'!$T$2:$T$5000,FALSE,'Station Responses'!$K$2:$K$5000,0),"") | K29: =IFERROR(AVERAGEIFS('Station Responses'!$K$2:$K$5000,'Station Responses'!$F$2:$F$5000,"C1B1",'Station Responses'!$T$2:$T$5000,FALSE,'Station Responses'!$S$2:$S$5000,"upper")-AVERAGEIFS('Station Responses'!$K$2:$K$5000,'Station Responses'!$F$2:$F$5000,"C1B1",'Station Responses'!$T$2:$T$5000,FALSE,'Station Responses'!$S$2:$S$5000,"lower"),"") | L29: =IFERROR(AVERAGEIFS('Station Responses'!$P$2:$P$5000,'Station Responses'!$F$2:$F$5000,"C1B1",'Station Responses'!$T$2:$T$5000,FALSE,'Station Responses'!$P$2:$P$5000,">0"),"") | M29: =IFERROR(COUNTIFS('Station Responses'!$F$2:$F$5000,"C1B1",'Station Responses'!$T$2:$T$5000,FALSE,'Station Responses'!$O$2:$O$5000,">0")/H29,"") | N29: =IF(H29<5,"too few answers",IF(I29<0.3,"very hard — review teaching or item",IF(I29>0.9,"very easy",IF(AND(K29<>"",K29<0.2),"low discrimination — review item","OK")))) | O29: Class III is a teaching estimate; trends and response matter more than a bucket.
